<?xml version="1.0"?>
<robot xmlns:xacro="http://www.ros.org/wiki/xacro" name="my_robot">

  <link name="base_link">
    <visual>
      <geometry>
        <box size="0.4 0.3 0.1"/>
      </geometry>
      <material name="blue">
        <color rgba="0.0 0.0 1.0 1.0"/>
      </material>
    </visual>
    <collision>
      <geometry>
        <box size="0.4 0.3 0.1"/>
      </geometry>
    </collision>
    <inertial>
        <mass value="5.0"/>
        <inertia ixx="0.04" ixy="0.0" ixz="0.0" iyy="0.07" iyz="0.0" izz="0.1"/>
    </inertial>
  </link>

  <link name="left_wheel_link">
    <visual>
      <geometry>
        <cylinder radius="0.05" length="0.04"/>
      </geometry>
      <material name="black">
        <color rgba="0.0 0.0 0.0 1.0"/>
      </material>
    </visual>
    <collision>
      <geometry>
        <cylinder radius="0.05" length="0.04"/>
      </geometry>
    </collision>
     <inertial>
        <mass value="0.5"/>
        <inertia ixx="0.0006" ixy="0.0" ixz="0.0" iyy="0.0006" iyz="0.0" izz="0.001"/>
    </inertial>
  </link>

  <link name="right_wheel_link">
    <visual>
      <geometry>
        <cylinder radius="0.05" length="0.04"/>
      </geometry>
      <material name="black"/>
    </visual>
    <collision>
      <geometry>
        <cylinder radius="0.05" length="0.04"/>
      </geometry>
    </collision>
    <inertial>
        <mass value="0.5"/>
        <inertia ixx="0.0006" ixy="0.0" ixz="0.0" iyy="0.0006" iyz="0.0" izz="0.001"/>
    </inertial>
  </link>

  <link name="caster_link">
    <visual>
      <geometry>
        <sphere radius="0.03"/>
      </geometry>
      <material name="grey">
        <color rgba="0.5 0.5 0.5 1.0"/>
      </material>
    </visual>
    <collision>
      <geometry>
        <sphere radius="0.03"/>
      </geometry>
    </collision>
    <inertial>
        <mass value="0.2"/>
        <inertia ixx="0.000048" ixy="0.0" ixz="0.0" iyy="0.000048" iyz="0.0" izz="0.000048"/>
    </inertial>
  </link>

  <link name="camera_link">
     <visual>
      <geometry>
        <box size="0.03 0.05 0.05"/>
      </geometry>
      <material name="red">
        <color rgba="1.0 0.0 0.0 1.0"/>
      </material>
    </visual>
     <collision>
      <geometry>
        <box size="0.03 0.05 0.05"/>
      </geometry>
    </collision>
     <inertial>
        <mass value="0.1"/>
        <inertia ixx="0.00004" ixy="0.0" ixz="0.0" iyy="0.00004" iyz="0.0" izz="0.00004"/>
    </inertial>
  </link>

  <joint name="left_wheel_joint" type="continuous">
    <parent link="base_link"/>
    <child link="left_wheel_link"/>
    <origin xyz="0.1 0.17 0.0" rpy="-1.5707 0 0"/>
    <axis xyz="0 0 1"/>
  </joint>

  <joint name="right_wheel_joint" type="continuous">
    <parent link="base_link"/>
    <child link="right_wheel_link"/>
    <origin xyz="0.1 -0.17 0.0" rpy="1.5707 0 0"/>
    <axis xyz="0 0 -1"/>
  </joint>

  <joint name="caster_joint" type="fixed">
    <parent link="base_link"/>
    <child link="caster_link"/>
    <origin xyz="-0.15 0.0 -0.02" rpy="0 0 0"/>
  </joint>

  <joint name="camera_joint" type="fixed">
    <parent link="base_link"/>
    <child link="camera_link"/>
    <origin xyz="0.18 0.0 0.05" rpy="0 0 0"/>
  </joint>

  <gazebo>
    <plugin name="diff_drive_controller" filename="libgazebo_ros_diff_drive.so">
      <ros>
        <command_topic>cmd_vel</command_topic>
        <odometry_topic>odom</odometry_topic>
        <odometry_frame>odom</odometry_frame>
        <robot_base_frame>base_link</robot_base_frame>
      </ros>

      <left_joint>left_wheel_joint</left_joint>
      <right_joint>right_wheel_joint</right_joint>
      <wheel_separation>0.34</wheel_separation>
      <wheel_diameter>0.1</wheel_diameter>
      
      <publish_odom>true</publish_odom>
      <publish_odom_tf>true</publish_odom_tf>
      <publish_wheel_tf>false</publish_wheel_tf>

      <update_rate>100</update_rate>
    </plugin>
  </gazebo>

  <gazebo reference="camera_link">
    <sensor type="camera" name="camera_sensor">
      <update_rate>30.0</update_rate>
      <camera name="head">
        <horizontal_fov>1.396</horizontal_fov>
        <image>
          <width>640</width>
          <height>480</height>
          <format>R8G8B8</format>
        </image>
        <clip>
          <near>0.02</near>
          <far>300</far>
        </clip>
      </camera>
      <plugin name="camera_controller" filename="libgazebo_ros_camera.so">
          <ros>
              <namespace>/camera</namespace>
              <image_topic>image_raw</image_topic> 
              <info_topic>camera_info</info_topic> 
          </ros>

          <camera_name>camera_sensor</camera_name> 
          
          <frame_name>camera_link</frame_name> 

          <hack_baseline>0.07</hack_baseline> 
          <min_depth>0.001</min_depth>
          <max_depth>100.0</max_depth>
      </plugin>
    </sensor>
  </gazebo>

  <material name="blue">
     <color rgba="0.0 0.0 1.0 1.0"/>
   </material>
   <material name="black">
     <color rgba="0.0 0.0 0.0 1.0"/>
   </material>
    <material name="grey">
     <color rgba="0.5 0.5 0.5 1.0"/>
   </material>
   <material name="red">
     <color rgba="1.0 0.0 0.0 1.0"/>
   </material>

</robot>
